Workbook

Sheet Sources
A1: CoreWeave, Inc. (CRWV, CIK 0001769628) - Source Filings
A2: R1 output. Raw tabs contain ONLY tables copied from these documents. Units: $ in millions unless the tab header says otherwise.
A3: ANALYSIS DATE: August 13, 2026. Use only information public on or before that date. Financials as of June 30, 2026 (Q2 2026 10-Q); capitalization pro forma for subsequent events disclosed by then (DDTL 5.5 facility, Aug 2026 revolver draw). Exclude anything later (e.g., Sep 2026 convertible notes, Q3 results).
A4: # | B4: Document | C4: Form | D4: Filed | E4: Period covered | F4: Accession no. | G4: Used for | H4: Raw tabs | I4: Link
A5: 1 | B5: Quarterly report Q2 2026 | C5: 10-Q | D5: 2026-08-12 | E5: Quarter / 6M ended 2026-06-30 | F5: 0001769628-26-000366 | G5: Latest GAAP statements; Note 10 debt tables + MD&A liquidity (R4); debt note text (R5) | H5: 10Q_BS, 10Q_IS, 10Q_CF, 10Q_Debt, 10Q_DebtText | I5: https://www.sec.gov/Archives/edgar/data/1769628/000176962826000366/crwv-20260630.htm
A6: 2 | B6: Annual report FY2025 | C6: 10-K | D6: 2026-03-02 | E6: Year ended 2025-12-31 | F6: 0001769628-26-000104 | G6: Full-year GAAP statements (for LTM = FY25 + 6M26 - 6M25); full business description; full debt note | H6: 10K_BS, 10K_IS, 10K_CF, 10K_DebtText | I6: https://www.sec.gov/Archives/edgar/data/1769628/000176962826000104/0001769628-26-000104-index.htm
A7: 3 | B7: Q2 2026 earnings press release | C7: 8-K Item 2.02, Ex.99.1 | D7: 2026-08-11 | E7: Quarter / 6M ended 2026-06-30 | F7: 0001769628-26-000362 | G7: Non-GAAP reconciliations (Adj. EBITDA etc.) - not in the 10-Q | H7: PR_Q2-26 | I7: https://www.sec.gov/Archives/edgar/data/1769628/000176962826000362/coreweave2q26earningspress.htm
A8: 4 | B8: Q4 2025 earnings press release | C8: 8-K Item 2.02, Ex.99.1 | D8: 2026-02-26 | E8: Quarter / year ended 2025-12-31 | F8: 0001769628-26-000094 | G8: FY2025 non-GAAP reconciliations (for LTM Adj. EBITDA) | H8: PR_Q4-25 | I8: https://www.sec.gov/Archives/edgar/data/1769628/000176962826000094/coreweave4q25earningspress.htm
A9: 5 | B9: DDTL 5.5 facility closing | C9: 8-K Items 1.01, 2.03, 7.01; Ex.10.2, Ex.99.1 | D9: 2026-08-10 | E9: Event date 2026-08-07 | F9: 0001769628-26-000357 | G9: Subsequent event: new $2.6bn facility (with 10-Q Note 16) - pro forma capitalization at 2026-08-13 | H9: Subsequent | I9: https://www.sec.gov/Archives/edgar/data/1769628/000176962826000357/0001769628-26-000357-index.htm
A10: 6 | B10: Q3 and FY 2026 Outlook Presentation | C10: IR website PDF (not an SEC filing) | D10: 2026-08-11 | E10: Guidance for Q3'26 and FY'26 | F10: n/a | G10: Company guidance: revenue, adj. operating income, interest expense, capex, exit ARR (Funding Need) | H10: Guidance (A) | I10: https://s205.q4cdn.com/133937190/files/doc_financials/2026/q2/CoreWeave-Q2-26-Earnings-Outlook-Presentation.pdf
A11: 7 | B11: Q2'26 Earnings Presentation | C11: IR website PDF (not an SEC filing) | D11: 2026-08-11 | E11: Quarter / 6M ended 2026-06-30 | F11: n/a | G11: Company definition of capex and its calculation (gross PP&E increase less change in CIP) - the basis of the capex guidance | H11: Guidance (B) | I11: https://s205.q4cdn.com/133937190/files/doc_financials/2026/q2/CoreWeave-Q2-26-Earnings-Presentation.pdf
A12: 8 | B12: Q2 2026 earnings call transcript | C12: IR website PDF (FactSet corrected transcript) | D12: 2026-08-11 (call date) | E12: Quarter ended 2026-06-30 | F12: n/a | G12: CFO remarks on capex, liquidity, guidance; contracted power and 2030 target | H12: Guidance (C) | I12: https://s205.q4cdn.com/133937190/files/doc_financials/2026/q2/CRWV-US-CORRECTED-TRANSCRIPT-CoreWeave-Q2-2026-Earnings-Call-11August2026.pdf
A14: Progress
A15: R1-R3 done: this list, 10Q_* and 10K_* statements, PR_* non-GAAP tables. R4 done: 10Q_Debt (Note 10 tables from R32 + MD&A liquidity table).
A16: R5 done: 10Q_DebtText (Q2 10-Q Note 10 full text, R16) and 10K_DebtText (FY25 10-K Note 10 full text, R18 - terms of older debt the 10-Q does not repeat).
A17: R6 done: Subsequent (10-Q Note 16 + DDTL 5.5 8-K body, press release, parent guarantee s.2.1). Sep 2026 convertible notes excluded (after analysis date). Raw is complete.
A18: R7 done (added after Step 1, for Step 2 Funding Need): Guidance - Outlook Presentation slide 3, Earnings Presentation capex definition and calculation (slides 8, 14, 16), CFO guidance remarks from the call transcript. Company material, not SEC filings.
A20: How these were found on EDGAR
A21: 1. sec.gov > EDGAR full-text / company search > 'CoreWeave' > company page (CIK 0001769628).
A22: 2. Filter Filing Type = 10-Q / 10-K: take the latest of each. Filter = 8-K: earnings releases are the 8-Ks with Item 2.02 (Results of Operations).
A23: 3. Open a filing's index page > 'Interactive Data' (R pages): each statement is its own page (R2 = balance sheet, R4 = income statement, R6 = cash flow in this 10-Q). Financial_Report.xlsx on the same page has all of them in Excel.
A24: 4. Press releases have no R pages: open Ex.99.1 and copy the reconciliation tables at the end.
A26: Copy rules used (what was and was NOT changed)
A27: Kept exactly: every row label, row order, column headers, footnote markers [1], section/abstract rows, units shown in each table title.
... A31: Verification: the copied text of all 6 GAAP tables and 6 press-release tables was fingerprinted (SHA-256) against the SEC pages and matched exactly.

Sheet 10Q_BS
A1: 10-Q Q2 2026 - Condensed Consolidated Balance Sheets
A2: Source: 10-Q filed 2026-08-12, R2.htm
A3: https://www.sec.gov/Archives/edgar/data/1769628/000176962826000366/R2.htm
A4: Copied as shown on the SEC R page.
A6: CONDENSED CONSOLIDATED BALANCE SHEETS - USD ($) $ in Millions | B6: Jun. 30, 2026 | C6: Dec. 31, 2025
A7: Current assets
A8: Cash and cash equivalents | B8: 5524 | C8: 3127
A9: Restricted cash and cash equivalents, current | B9: 873 | C9: 819
A10: Marketable securities | B10: 15 | C10: 34
A11: Accounts receivable, net | B11: 2541 | C11: 3169
A12: Prepaid expenses and other current assets | B12: 567 | C12: 339
A13: Total current assets | B13: 9520 | C13: 7488
A14: Restricted cash and cash equivalents, non-current | B14: 507 | C14: 184
A15: Property and equipment, net | B15: 46736 | C15: 30557
A16: Operating lease right-of-use assets | B16: 16595 | C16: 8231
A17: Intangible assets, net | B17: 245 | C17: 235
A18: Goodwill | B18: 1101 | C18: 1101
A19: Other non-current assets | B19: 2366 | C19: 1506
A20: Total assets | B20: 77070 | C20: 49302
A21: Current liabilities
A22: Accounts payable | B22: 3633 | C22: 1623
A23: Accrued liabilities | B23: 6424 | C23: 5773
A24: Recourse debt, current | B24: 6235 | C24: 6118
A25: Non-recourse debt, current | B25: 1278 | C25: 590
A26: Deferred revenue, current | B26: 2686 | C26: 1709
A27: Operating lease liabilities, current | B27: 584 | C27: 427
A28: Finance lease liabilities, current | B28: 7 | C28: 38
A29: Other current liabilities | B29: 70 | C29: 162
A30: Total current liabilities | B30: 20917 | C30: 16440
A31: Recourse debt, non-current | B31: 25170 | C31: 14608
A32: Non-recourse debt, non-current | B32: 2385 | C32: 57
A33: Deferred revenue, non-current | B33: 7006 | C33: 6476
... A38: Total liabilities | B38: 72046 | C38: 45967
A39: Commitments and contingencies (Note 9)
A40: Stockholders' equity
A41: Preferred stock | B41: 0 | C41: 0
A42: Treasury stock, at cost | B42: -34 | C42: -34
A43: Additional paid-in capital | B43: 9085 | C43: 6012
A44: Accumulated other comprehensive loss | B44: -18 | C44: 0
A45: Accumulated deficit | B45: -4009 | C45: -2643
...

Sheet 10Q_IS
A1: 10-Q Q2 2026 - Condensed Consolidated Statements of Operations
A2: Source: 10-Q filed 2026-08-12, R4.htm
A3: https://www.sec.gov/Archives/edgar/data/1769628/000176962826000366/R4.htm
A4: Copied as shown on the SEC R page.
A6: CONDENSED CONSOLIDATED STATEMENTS OF OPERATIONS AND COMPREHENSIVE LOSS - USD ($) shares in Millions, $ in Millions | B6: 3 Months Ended | D6: 6 Months Ended
B7: Jun. 30, 2026 | C7: Jun. 30, 2025 | D7: Jun. 30, 2026 | E7: Jun. 30, 2025
A8: Income Statement [Abstract]
A9: Revenue | B9: 2575 | C9: 1212 | D9: 4653 | E9: 2194
A10: Operating expenses:
A11: Cost of revenue | B11: 879 | C11: 313 | D11: 1595 | E11: 575
A12: Technology and infrastructure | B12: 1507 | C12: 670 | D12: 2780 | E12: 1231
A13: Sales and marketing | B13: 60 | C13: 36 | D13: 129 | E13: 47
A14: General and administrative | B14: 178 | C14: 174 | D14: 342 | E14: 349
A15: Total operating expenses | B15: 2624 | C15: 1193 | D15: 4846 | E15: 2202
A16: Operating income (loss) | B16: -49 | C16: 19 | D16: -193 | E16: -8
A17: Gain (loss) on fair value adjustments | B17: 0 | C17: 0 | D17: 0 | E17: 27
A18: Interest expense, net | B18: -640 | C18: -267 | D18: -1176 | E18: -531
A19: Other income (expense), net | B19: 125 | C19: 6 | D19: 149 | E19: 1
A20: Loss before income taxes | B20: -564 | C20: -242 | D20: -1220 | E20: -511
A21: Provision for income taxes | B21: 62 | C21: 48 | D21: 146 | E21: 94
A22: Net loss | B22: -626 | C22: -290 | D22: -1366 | E22: -605
... A30: Weighted-average shares used in computing net loss per share attributable to common stockholders, diluted (in shares) | B30: 551 | C30: 487 | D30: 539 | E30: 369
A32: Checks (added by us, NOT part of the SEC table) - all should be 0
A33: Total operating expenses | B33: =SUM(B11:B14)-B15 | C33: =SUM(C11:C14)-C15 | D33: =SUM(D11:D14)-D15 | E33: =SUM(E11:E14)-E15
A34: Operating income | B34: =B9-B15-B16 | C34: =C9-C15-C16 | D34: =D9-D15-D16 | E34: =E9-E15-E16
A35: Loss before income taxes | B35: =SUM(B16:B19)-B20 | C35: =SUM(C16:C19)-C20 | D35: =SUM(D16:D19)-D20 | E35: =SUM(E16:E19)-E20
A36: Net loss | B36: =B20-B21-B22 | C36: =C20-C21-C22 | D36: =D20-D21-D22 | E36: =E20-E21-E22
A37: Total comprehensive loss | B37: =B22+B23-B24 | C37: =C22+C23-C24 | D37: =D22+D23-D24 | E37: =E22+E23-E24

Sheet 10Q_CF
A1: 10-Q Q2 2026 - Condensed Consolidated Statements of Cash Flows
A2: Source: 10-Q filed 2026-08-12, R6.htm
A3: https://www.sec.gov/Archives/edgar/data/1769628/000176962826000366/R6.htm
A4: NOTE: this R page is labelled '$ in Thousands' (1,366,000 = $1,366 million). The 10-Q document itself shows $ in millions. Copied as shown.
A6: CONDENSED CONSOLIDATED STATEMENTS OF CASH FLOWS - USD ($) $ in Thousands | B6: 6 Months Ended
B7: Jun. 30, 2026 | C7: Jun. 30, 2025
A8: Cash flows from operating activities:
A9: Net loss | B9: -1366000 | C9: -605000
A10: Adjustments to reconcile net loss to net cash provided by operating activities
A11: Depreciation and amortization | B11: 2540000 | C11: 1003000
A12: Amortization of debt discounts and issuance costs and accretion of redemption premiums | B12: 86000 | C12: 67000
A13: Stock-based compensation expense | B13: 318000 | C13: 329000
A14: Non-cash lease expense | B14: 365000 | C14: 144000
A15: Deferred income taxes | B15: 140000 | C15: 91000
A16: Gain on fair value adjustments | B16: 0 | C16: -27000
A17: Other non-cash reconciling items | B17: 97000 | C17: 39000
A18: Changes in operating assets and liabilities, net of effect of business acquisitions:
A19: Accounts receivable | B19: 607000 | C19: -1505000
A20: Prepaid expenses and other assets | B20: -611000 | C20: -70000
A21: Accounts payable and accrued expenses | B21: 304000 | C21: -289000
A22: Deferred revenue | B22: 1365000 | C22: 743000
A23: Lease liabilities | B23: -182000 | C23: -110000
A24: Net cash provided by (used in) operating activities | B24: 3663000 | C24: -190000
A25: Cash flows from investing activities:
A26: Purchase of property and equipment, including capitalized internal-use software | B26: -14117000 | C26: -3860000
A27: Maturities and sales of marketable securities | B27: 18000 | C27: 29000
A28: Investments related to joint ventures | B28: -550000 | C28: -32000
A29: Purchase of strategic investments | B29: -138000 | C29: 0
A30: Sales of warrants received as lease incentive | B30: 0 | C30: 101000
A31: Issuance of notes receivable | B31: 0 | C31: -73000
A32: Business combination, net of cash acquired | B32: 0 | C32: -46000
A33: Other investing activities | B33: -87000 | C33: 6000
A34: Net cash used in investing activities | B34: -14874000 | C34: -3875000
A35: Cash flows from financing activities:
A36: Proceeds from issuance of debt, net | B36: 16747000 | C36: 4396000
A37: Repayments of debt | B37: -5219000 | C37: -1575000
A38: Purchase of capped calls related to convertible senior notes | B38: -492000 | C38: 0
A39: Issuance of common stock in private placements, net of issuance costs | B39: 2982000 | C39: 0
A40: Payment of tax withholdings on settlement of restricted stock units | B40: 0 | C40: -133000
A41: Proceeds from initial public offering, net of underwriting discounts and commissions | B41: 0 | C41: 1491000
...

Sheet 10Q_Debt
A1: 10-Q Q2 2026 - Note 10 Debt tables + MD&A liquidity table
A2: Source: 10-Q filed 2026-08-12. Tables 1-4 from R32.htm 'Debt (Tables)'; table 5 from the 10-Q document, Item 2 MD&A, Liquidity and Capital Resources
A3: https://www.sec.gov/Archives/edgar/data/1769628/000176962826000366/R32.htm
A4: Copied as shown ($ in millions). Rates like '15%' stored as 0.15; '—' stored as 0. Footnotes copied word for word below each table.
A6: Table 1. The total debt obligations are as follows (dollars in millions)
B7: Maturities | C7: EffectiveInterestRates | D7: June 30,2026 | E7: December 31,2025
A8: Recourse debt:
A9: DDTL 1.0 Facility | B9: Mar 2028 | C9: 0.15 | D9: 1300 | E9: 1553
A10: DDTL 2.0 Facility | B10: Aug 2030 | C10: 0.11 | D10: 3190 | E10: 5037
A11: DDTL 2.1 Facility | B11: Mar 2031 | C11: 0.09 | D11: 3000 | E11: 2741
A12: DDTL 3.0 Facility | B12: Aug 2030 | C12: 0.09 | D12: 2215 | E12: 340
A13: DDTL 5.0 Facility | B13: Nov 2031 | C13: 0.09 | D13: 1101 | E13: 0
A14: 2030 Senior Notes | B14: Jun 2030 | C14: 0.1 | D14: 2000 | E14: 2000
A15: 2031 9.00% Senior Notes | B15: Feb 2031 | C15: 0.1 | D15: 1750 | E15: 1750
A16: 2031 9.75% Senior Notes | B16: Oct 2031 | C16: 0.1 | D16: 2750 | E16: 0
A17: 2032 9.625% Senior Notes | B17: Jul 2032 | C17: 0.1 | D17: 1250 | E17: 0
A18: 2032 EUR Senior Notes(1) | B18: Jul 2032 | C18: 0.09 | D18: 2279 | E18: 0
A19: 2031 Convertible Senior Notes | B19: Dec 2031 | C19: 0.02 | D19: 2588 | E19: 2588
A20: 2032 Convertible Senior Notes | B20: Oct 2032 | C20: 0.02 | D20: 4000 | E20: 0
... A24: Magnetar Loan | B24: Jan 2029 | C24: 0.12 | D24: 189 | E24: 273
A25: Less: Unamortized discount and issuance costs | D25: -427 | E25: -242
A26: Total recourse debt, net of unamortized discount and issuance costs | D26: 31405 | E26: 20726
A27: Less: Recourse debt, current | D27: -6235 | E27: -6118
A28: Total recourse debt, non-current | D28: 25170 | E28: 14608
A29: Non-recourse debt:
A30: DDTL 4.0 Facility | B30: Mar 2032 | C30: 0.07 | D30: 2837 | E30: 0
A31: OEM and Software License Financing Arrangements | B31: Aug 2026 - Aug 2028 | C31: 0.09 | D31: 882 | E31: 647
A32: Less: Unamortized discount and issuance costs | D32: -56 | E32: 0
A33: Total non-recourse debt, net of unamortized discount and issuance costs | D33: 3663 | E33: 647
A34: Less: Non-recourse debt, current | D34: -1278 | E34: -590
A35: Total non-recourse debt, non-current | D35: 2385 | E35: 57
A36: (1) In June 2026, the Company entered into cross currency interest rate swaps designated as a fair value hedge, to hedge changes in the fair value on the 2032 EUR Senior Notes, attributable to changes in foreign currency exchange rate.
A38: Table 2. During the six months ended June 30, 2026, the Company entered into DDTL facilities and issued senior notes as follows (dollars in millions)
B39: Date of Issuance | C39: Stated Interest Rates(1) | D39: Amount(2)
A40: DDTL 4.0 Facility | B40: March 2026 | C40: SOFR + 2.25%; Treasury + 2.00% | D40: 8500
A41: DDTL 5.0 Facility | B41: May 2026 | C41: SOFR + 4.50% | D41: 3100
A42: 2031 9.75% Senior Notes | B42: April 2026 | C42: 9.75% | D42: 2750
A43: 2032 9.625% Senior Notes | B43: June 2026 | C43: 9.625% | D43: 1250
A44: 2032 EUR Senior Notes | B44: June 2026 | C44: 8.50% | D44: 2000 | E44: € (source shows € 2,000)
A45: 2032 Convertible Senior Notes | B45: April 2026 | C45: 1.75% | D45: 4000
...

Sheet 10Q_DebtText
A1: 10-Q Q2 2026 - Note 10 Debt (full text)
A2: Source: 10-Q filed 2026-08-12, R16.htm 'Debt'
A3: https://www.sec.gov/Archives/edgar/data/1769628/000176962826000366/R16.htm
A4: Full note text, word for word, one paragraph per row, in the original order. Column B repeats the nearest heading above (navigation only). Where SEC splits a paragraph across a page break it stays split. [TABLE] = a table in the note: the first four are copied as numbers in 10Q_Debt (Tables 1-4); the last one (DCSP financing obligation) is not copied.
A6: ¶ | B6: Section (heading in source) | C6: Text (verbatim)
A7: 1 | B7: (note intro) | C7: The total debt obligations are as follows (dollars in millions):
A8: 2 | B8: (note intro) | C8: (1) In June 2026, the Company entered into cross currency interest rate swaps designated as a fair value hedge, to hedge changes in the fair value on the 2032 EUR Senior Notes, attributable to changes in foreign currency exchange rate.
A9: 3 | B9: (note intro) | C9: [TABLE]
A10: 4 | B10: (note intro) | C10: As of June 30, 2026, the Company's weighted-average interest rate on short-term debt instruments related to certain of the OEM Financing Arrangements was 9%.
A11: 5 | B11: (note intro) | C11: Non-recourse debt represents debt facilities and financing arrangements entered into by certain of the Company’s subsidiaries for which recourse is limited to the assets of the applicable subsidiaries. CoreWeave, Inc., the ultimate parent company, is not otherwise liable for such debt, except in cases where the Company provides limited guarantees under which recourse may arise only upon specified events, such as actual fraud, willful misconduct, misappropriation of collateral, certain voluntary or consented bankruptcy actions, or other customary non-recourse carve-out obligations. These limited guarantees do not represent general guarantees of repayment of principal, interest or other ordinary debt service payments. Recourse debt represents debt facilities and financing arrangements that are either direct obligations of
A12: 6 | B12: (note intro) | C12: CoreWeave, Inc. or obligations of certain of the Company’s subsidiaries that are unconditionally and irrevocably guaranteed by CoreWeave, Inc.
A13: 7 | B13: (note intro) | C13: As of June 30, 2026, the future principal payments for the Company's total debt were as follows (in millions):
A14: 8 | B14: (note intro) | C14: [TABLE]
A15: 9 | B15: (note intro) | C15: The total interest expense for the Company's debt obligations was as follows (in millions):
A16: 10 | B16: (note intro) | C16: [TABLE]
A17: 11 | B17: (note intro) | C17: During the six months ended June 30, 2026, the Company entered into DDTL facilities and issued senior notes (each as defined in this Note 10—Debt) as follows (dollars in millions):
A18: 12 | B18: (note intro) | C18: [TABLE]
... A73: 67 | B73: DCSP Financing Arrangements | C73: During the three months ended June 30, 2026, the Company reassessed the DCSP as a VIE following changes affecting the adequacy of the DCSP's equity investment at risk. The Company concluded that it was not the primary beneficiary of the DCSP because it lacked the power to direct the activities that most significantly impact the DCSP's economic performance. Accordingly, the Company did not consolidate the DCSP. The Company's maximum exposure to loss related to the DCSP consists of the carrying amount of the DCSP Note Receivable and the Company's commitment to fund the remaining completion work at the data center. This funding commitment is not subject to a contractual cap; however, the Company estimates the remaining funding obligation to be not material. Amounts funded under this commitment are recoverable from the DCSP only through contingent, unsecured reimbursement rights.

Sheet 10K_BS
A1: 10-K FY2025 - Consolidated Balance Sheets
A2: Source: 10-K filed 2026-03-02, R3.htm
A3: https://www.sec.gov/Archives/edgar/data/1769628/000176962826000104/R3.htm
A4: Copied as shown. Column B = footnote marker column on the SEC page; [1] = footnote at the bottom of the table.
A6: CONSOLIDATED BALANCE SHEETS - USD ($) shares in Millions, $ in Millions | C6: Dec. 31, 2025 | D6: Dec. 31, 2024
A7: Current assets
A8: Cash and cash equivalents | C8: 3127 | D8: 1361
A9: Restricted cash and cash equivalents, current | C9: 819 | D9: 37
A10: Marketable securities | C10: 34 | D10: 0
A11: Accounts receivable, net | C11: 3169 | D11: 417
A12: Prepaid expenses and other current assets | C12: 339 | D12: 101
A13: Total current assets | C13: 7488 | D13: 1916
A14: Restricted cash and cash equivalents, non-current | C14: 184 | D14: 637
A15: Restricted marketable securities, non-current | C15: 0 | D15: 29
A16: Property and equipment, net | C16: 30557 | D16: 11915
A17: Operating lease right-of-use assets | C17: 8231 | D17: 2590
A18: Intangible assets, net | C18: 235 | D18: 5
A19: Goodwill | C19: 1101 | D19: 20
A20: Other non-current assets | B20: [1] | C20: 1506 | D20: 721
A21: Total assets | C21: 49302 | D21: 17833
A22: Current liabilities
A23: Accounts payable | C23: 1623 | D23: 868
A24: Accrued liabilities | C24: 5773 | D24: 356
A25: Debt, current | B25: [1] | C25: 6708 | D25: 2468
A26: Deferred revenue, current | C26: 1709 | D26: 769
A27: Operating lease liabilities, current | C27: 427 | D27: 213
A28: Finance lease liabilities, current | C28: 38 | D28: 58
A29: Other current liabilities | B29: [1] | C29: 162 | D29: 231
A30: Total current liabilities | C30: 16440 | D30: 4963
A31: Debt, non-current | B31: [1] | C31: 14665 | D31: 5458
A32: Derivative and warrant liabilities | C32: 1 | D32: 200
A33: Deferred revenue, non-current | C33: 6476 | D33: 3295
A34: Operating lease liabilities, non-current | C34: 7768 | D34: 2389
A35: Finance lease liabilities, non-current | C35: 216 | D35: 34
A36: Deferred tax liabilities, non-current | C36: 115 | D36: 149
A37: Other non-current liabilities | C37: 286 | D37: 37
A38: Total liabilities | C38: 45967 | D38: 16525
A39: Commitments and contingencies (Note 9)
A40: Stockholders' equity (deficit)
A41: Preferred stock, $0.000005 par value per share, 100 and no shares authorized as of December 31, 2025 and 2024, respectively; no shares issued and outstanding as of December 31, 2025 and 2024 | C41: 0 | D41: 0
...

Sheet 10K_IS
A1: 10-K FY2025 - Consolidated Statements of Operations
A2: Source: 10-K filed 2026-03-02, R5.htm
A3: https://www.sec.gov/Archives/edgar/data/1769628/000176962826000104/R5.htm
A4: Copied as shown. Column B = footnote marker column.
A6: CONSOLIDATED STATEMENTS OF OPERATIONS AND COMPREHENSIVE LOSS - USD ($) shares in Millions, $ in Millions | C6: 12 Months Ended
C7: Dec. 31, 2025 | D7: Dec. 31, 2024 | E7: Dec. 31, 2023
A8: Income Statement [Abstract]
A9: Revenue | C9: 5131 | D9: 1915 | E9: 229
A10: Operating expenses:
A11: Cost of revenue | C11: 1453 | D11: 493 | E11: 69
A12: Technology and infrastructure | C12: 2929 | D12: 961 | E12: 131
A13: Sales and marketing | C13: 144 | D13: 18 | E13: 13
A14: General and administrative | C14: 651 | D14: 119 | E14: 30
A15: Total operating expenses | C15: 5177 | D15: 1591 | E15: 243
A16: Operating income (loss) | C16: -46 | D16: 324 | E16: -14
A17: Gain (loss) on fair value adjustments | C17: 27 | D17: -756 | E17: -534
A18: Interest expense, net | B18: [1] | C18: -1229 | D18: -361 | E18: -28
A19: Other income, net | C19: 33 | D19: 49 | E19: 18
A20: Loss before income taxes | C20: -1215 | D20: -744 | E20: -558
A21: Provision for (benefit from) income taxes | C21: -48 | D21: 119 | E21: 36
A22: Net loss and comprehensive loss | C22: -1167 | D22: -863 | E22: -594
A23: Net loss attributable to common stockholders, basic | C23: -1196 | D23: -937 | E23: -594
A24: Net loss attributable to common stockholders, diluted | C24: -1223 | D24: -937 | E24: -594
A25: Net loss per share attributable to common stockholders, basic (in usd per share ) | C25: -2.75 | D25: -4.3 | E25: -3.09
A26: Net loss per share attributable to common stockholders, diluted (in usd per share ) | C26: -2.81 | D26: -4.3 | E26: -3.09
A27: Weighted-average shares used in computing net loss per share attributable to common stockholders, basic (in shares) | C27: 435 | D27: 218 | E27: 192
A28: Weighted-average shares used in computing net loss per share attributable to common stockholders, diluted (in shares) | C28: 436 | D28: 218 | E28: 192
A30: [1] Refer to Note 14—Related-Party Transactions for further information on related party arrangements.
A32: Checks (added by us, NOT part of the SEC table) - all should be 0
A33: Total operating expenses | C33: =SUM(C11:C14)-C15 | D33: =SUM(D11:D14)-D15 | E33: =SUM(E11:E14)-E15
A34: Operating income | C34: =C9-C15-C16 | D34: =D9-D15-D16 | E34: =E9-E15-E16
A35: Loss before income taxes | C35: =SUM(C16:C19)-C20 | D35: =SUM(D16:D19)-D20 | E35: =SUM(E16:E19)-E20
A36: Net loss | C36: =C20-C21-C22 | D36: =D20-D21-D22 | E36: =E20-E21-E22

Sheet 10K_CF
A1: 10-K FY2025 - Consolidated Statements of Cash Flows
A2: Source: 10-K filed 2026-03-02, R8.htm
A3: https://www.sec.gov/Archives/edgar/data/1769628/000176962826000104/R8.htm
A4: Copied as shown ($ in millions).
A6: CONSOLIDATED STATEMENTS OF CASH FLOWS - USD ($) $ in Millions | B6: 12 Months Ended
B7: Dec. 31, 2025 | C7: Dec. 31, 2024 | D7: Dec. 31, 2023
A8: Cash flows from operating activities:
A9: Net loss | B9: -1167 | C9: -863 | D9: -594
A10: Adjustments to reconcile net loss to net cash provided by operating activities
A11: Depreciation and amortization | B11: 2454 | C11: 863 | D11: 103
A12: Amortization of debt discounts and issuance costs and accretion of redemption premiums | B12: 110 | C12: 33 | D12: 16
A13: Stock-based compensation expense | B13: 630 | C13: 31 | D13: 15
A14: Non-cash lease expense | B14: 357 | C14: 123 | D14: 20
A15: Deferred income taxes | B15: -53 | C15: 113 | D15: 36
A16: Loss (gain) on fair value adjustments | B16: -27 | C16: 756 | D16: 534
A17: Debt extinguishment loss | B17: 19 | C17: 12 | D17: 0
A18: Other non-cash reconciling items | B18: 103 | C18: 3 | D18: 1
A19: Changes in operating assets and liabilities, net of effect of business acquisitions:
A20: Accounts receivable | B20: -2749 | C20: -280 | D20: -162
A21: Prepaid expenses and other assets | B21: -784 | C21: -514 | D21: -139
A22: Accounts payable and accrued expenses | B22: 253 | C22: 511 | D22: 27
A23: Deferred revenue | B23: 4174 | C23: 2049 | D23: 1986
A24: Lease liabilities | B24: -262 | C24: -88 | D24: -9
A25: Other liabilities | B25: 0 | C25: 0 | D25: -1
A26: Net cash provided by operating activities | B26: 3058 | C26: 2749 | D26: 1833
A27: Cash flows from investing activities:
A28: Purchase of property and equipment, including capitalized internal-use software | B28: -10309 | C28: -8702 | D28: -2943
A29: Purchases of marketable securities | B29: -47 | C29: -34 | D29: -172
A30: Maturities and sales of marketable securities | B30: 43 | C30: 188 | D30: 6
A31: Sales of warrants received as lease incentive | B31: 254 | C31: 0 | D31: 0
A32: Business combinations, net of cash acquired | B32: -108 | C32: 0 | D32: 0
A33: Issuance of notes receivable | B33: -90 | C33: -60 | D33: 0
A34: Other investing activities | B34: -14 | C34: -50 | D34: -39
A35: Net cash used in investing activities | B35: -10271 | C35: -8658 | D35: -3148
A36: Cash flows from financing activities:
A37: Proceeds from issuance of debt, net | B37: 11829 | C37: 7018 | D37: 1404
A38: Repayments of debt | B38: -3399 | C38: -589 | D38: -2
A39: Purchase of capped calls related to convertible senior notes | B39: -340 | C39: 0 | D39: 0
A40: Proceeds from initial public offering, net of underwriting discounts and commissions | B40: 1491 | C40: 0 | D40: 0
A41: Redeemable convertible preferred stock cash dividends paid | B41: -29 | C41: -58 | D41: 0
...

Sheet 10K_DebtText
A1: 10-K FY2025 - Note 10 Debt (full text)
A2: Source: 10-K filed 2026-03-02, R18.htm 'Debt'
A3: https://www.sec.gov/Archives/edgar/data/1769628/000176962826000104/R18.htm
A4: Full note text, word for word, one paragraph per row, in the original order. Column B repeats the nearest heading above (navigation only). Where SEC splits a paragraph across a page break it stays split. [TABLE] = a table in the note: Dec-25 tables not copied (superseded by the Q2 10-Q). Use this tab for terms of debt that the Q2 10-Q does not repeat (DDTL 1.0-3.0, 2030/2031 notes, 2031 converts, revolver history, OEM, Magnetar).
A6: ¶ | B6: Section (heading in source) | C6: Text (verbatim)
A7: 1 | B7: (note intro) | C7: The total debt obligations are as follows (dollars in millions):
A8: 2 | B8: (note intro) | C8: [TABLE]
A9: 3 | B9: (note intro) | C9: As of December 31, 2025, the future principal payments for the Company's total debt were as follows (in millions):
A10: 4 | B10: (note intro) | C10: [TABLE]
A11: 5 | B11: (note intro) | C11: The total interest expense for the Company's debt obligations was as follows (in millions):
A12: 6 | B12: (note intro) | C12: [TABLE]
A13: 7 | B13: (note intro) | C13: In the year ended December 31, 2025, the Company entered into DDTL Facilities and issued Senior Notes (each as defined in Note 10—Debt) as follows (dollars in millions):
A14: 8 | B14: (note intro) | C14: [TABLE]
A15: 9 | B15: (note intro) | C15: (1) DDTL Facilities are subject to an interest rate per annum equal to, at the Company's option, either the SOFR or the alternative base rate plus a spread.
A16: 10 | B16: (note intro) | C16: (2) Amounts represent borrowing capacity for the DDTL Facilities and the principal amounts for the Senior Notes.
A17: 11 | B17: Delayed Draw Term Loans ("DDTL") | C17: Delayed Draw Term Loans ("DDTL")
A18: 12 | B18: Delayed Draw Term Loans ("DDTL") | C18: In July 2023, the Company entered into a Delayed Draw Term Loan 1.0 Facility (as amended, the "DDTL 1.0 Facility"), which provided for a delayed draw term loan facility of up to $2.3 billion. The principal amount of the DDTL 1.0 Facility is required to be repaid in quarterly installments, with the final payment due on March 28, 2028.
... A71: 65 | B71: DCSP Financing Arrangements | C71: The DCSP Financing Arrangements allow for the net settlement of amounts due between the parties and meet the criteria for right of setoff in accordance with ASC 210, Balance Sheet. As of December 31, 2025, the gross amount of the DCSP Note Receivable was $304 million, which is presented net of the financing obligation and finance lease of $234 million. As of December 31, 2024, the gross amount of the DCSP Note Receivable was $224 million, which is presented net of the financing obligation of $116 million. The Company did not recognize any interest income during the year ended December 31, 2024, as the Company did not expect to be entitled to the accrued interest. The Company began recognizing interest income associated with this arrangement in March 2025. For the year ended December 31, 2025, the Company recognized $28 million of interest income in other income, net in the consolidated statements of operations and comprehensive loss. The total interest expense related to the financing obligation and finance lease associated with this arrangement for the year ended December 31, 2025 was $28 million and was not material for the years ended December 31, 2024 and 2023.

Sheet PR_Q2-26
A1: Q2 2026 Earnings Release - Non-GAAP Reconciliations
A2: Source: 8-K filed 2026-08-11 (Item 2.02), Exhibit 99.1
A3: https://www.sec.gov/Archives/edgar/data/1769628/000176962826000362/coreweave2q26earningspress.htm
A4: Company's own words (excerpt): To supplement our consolidated financial statements, which are prepared and presented in accordance with generally accepted accounting principles in the United States (“GAAP”), we use adjusted EBITDA and adjusted EBITDA margin, adjusted operating income (loss) and adjusted operating income (loss) margin, adjusted net income (loss) and adjusted net income (loss) margin, collectively, to help us evaluate our business. ... These non-GAAP financial measures are presented for supplemental informational purposes only, should not be considered a substitute for financial information presented in accordance with GAAP, and may be different from similarly titled non-GAAP measures used by other companies.
A6: Reconciliation of Net Loss to Adjusted EBITDA (in millions, except percentages)
B7: Three Months Ended June 30, | D7: Six Months Ended June 30,
B8: 2026 | C8: 2025 | D8: 2026 | E8: 2025
A9: Net loss | B9: -626 | C9: -290 | D9: -1366 | E9: -605
A10: Depreciation and amortization | B10: 1393 | C10: 559 | D10: 2540 | E10: 1003
A11: Interest expense, net | B11: 640 | C11: 267 | D11: 1176 | E11: 531
A12: Stock-based compensation | B12: 165 | C12: 145 | D12: 318 | E12: 329
A13: Provision for income taxes | B13: 62 | C13: 48 | D13: 146 | E13: 94
A14: Acquisition related costs(1) | B14: 1 | C14: 30 | D14: 2 | E14: 36
A15: Other (income) expense, net | B15: -125 | C15: -6 | D15: -149 | E15: -1
A16: (Gain) loss on fair value adjustments(2) | B16: 0 | C16: 0 | D16: 0 | E16: -27
A17: Adjusted EBITDA | B17: 1510 | C17: 753 | D17: 2667 | E17: 1360
A18: Revenue | B18: 2575 | C18: 1212 | D18: 4653 | E18: 2194
A19: Net loss margin | B19: -24 | C19: -24 | D19: -29 | E19: -28
A20: Adjusted EBITDA margin | B20: 59 | C20: 62 | D20: 57 | E20: 62
A21: (1) Acquisition related costs include direct transaction costs, such as due diligence, advisory, and professional services fees, and certain compensation and integration related expenses. We exclude acquisition related costs, as we believe these transaction-specific expenses are inconsistent in amount and frequency, and do not correlate to the operation of our business.
A22: (2) Represents adjustments related to recording our derivative liabilities at fair value at the end of each reporting period for our 2021 Convertible Senior Secured Notes, warrant liabilities related to our 2022 Senior Secured Notes, and the fair value remeasurement of the option liability in connection with our Series B redeemable convertible preferred stock. Refer to Note 3. Investments and Fair Value Measurements to our consolidated financial statements included in our Quarterly Report on Form 10-Q filed or to be filed with the SEC for the quarter ended June 30, 2026 for additional information.
A24: Reconciliation of Operating Loss to Adjusted Operating Income (in millions, except percentages)
B25: Three Months Ended June 30, | D25: Six Months Ended June 30,
B26: 2026 | C26: 2025 | D26: 2026 | E26: 2025
A27: Operating income (loss) | B27: -49 | C27: 19 | D27: -193 | E27: -8
A28: Stock-based compensation | B28: 165 | C28: 145 | D28: 318 | E28: 329
A29: Acquisition related costs(1) | B29: 1 | C29: 30 | D29: 2 | E29: 36
A30: Amortization of acquired intangibles(2) | B30: 11 | C30: 6 | D30: 22 | E30: 6
A31: Adjusted operating income | B31: 128 | C31: 200 | D31: 149 | E31: 363
A32: Revenue | B32: 2575 | C32: 1212 | D32: 4653 | E32: 2194
A33: Operating income (loss) margin | B33: -2 | C33: 2 | D33: -4 | E33: 0
A34: Adjusted operating income margin | B34: 5 | C34: 16 | D34: 3 | E34: 17
A35: (1) Acquisition related costs include direct transaction costs, such as due diligence, advisory, and professional services fees, and certain compensation and integration related expenses. We exclude acquisition related costs, as we believe these transaction-specific expenses are inconsistent in amount and frequency, and do not correlate to the operation of our business.
A36: (2) In the second quarter of 2025, we began including an adjustment for the amortization of acquired intangibles in our calculation of adjusted operating income. Prior period non-GAAP calculations for acquired intangible amortization are not being adjusted as these amounts were insignificant.
A38: Reconciliation of Net Loss to Adjusted Net Loss (in millions, except percentages)
B39: Three Months Ended June 30, | D39: Six Months Ended June 30,
B40: 2026 | C40: 2025 | D40: 2026 | E40: 2025
A41: Net loss | B41: -626 | C41: -290 | D41: -1366 | E41: -605
A42: Stock-based compensation | B42: 165 | C42: 145 | D42: 318 | E42: 329
A43: Loss on extinguishment of debt(1) | B43: 0 | C43: 9 | D43: 0 | E43: 10
...

Sheet PR_Q4-25
A1: Q4 2025 Earnings Release - Non-GAAP Reconciliations
A2: Source: 8-K filed 2026-02-26 (Item 2.02), Exhibit 99.1
A3: https://www.sec.gov/Archives/edgar/data/1769628/000176962826000094/coreweave4q25earningspress.htm
A4: Company's own words (excerpt): To supplement our consolidated financial statements, which are prepared and presented in accordance with generally accepted accounting principles in the United States (“GAAP”), we use adjusted EBITDA and adjusted EBITDA margin, adjusted operating income (loss) and adjusted operating income (loss) margin, adjusted net income (loss) and adjusted net income (loss) margin, collectively, to help us evaluate our business. ... These non-GAAP financial measures are presented for supplemental informational purposes only, should not be considered a substitute for financial information presented in accordance with GAAP, and may be different from similarly titled non-GAAP measures used by other companies.
A6: Reconciliation of Net Loss to Adjusted EBITDA (in millions, except percentages)
B7: Three Months Ended December 31, | D7: Twelve Months Ended December 31,
B8: 2025 | C8: 2024 | D8: 2025 | E8: 2024
A9: Net loss | B9: -452 | C9: -51 | D9: -1167 | E9: -863
A10: Depreciation and amortization | B10: 821 | C10: 365 | D10: 2454 | E10: 863
A11: Interest expense, net | B11: 388 | C11: 149 | D11: 1229 | E11: 361
A12: Stock-based compensation | B12: 157 | C12: 8 | D12: 630 | E12: 31
A13: Acquisition related costs(1) | B13: 9 | C13: 0 | D13: 55 | E13: 0
A14: (Gain) loss on fair value adjustments(2) | B14: 0 | C14: 7 | D14: -27 | E14: 756
A15: Other income, net | B15: -10 | C15: -14 | D15: -33 | E15: -48
A16: Provision for (benefit from) income taxes | B16: -15 | C16: 22 | D16: -48 | E16: 119
A17: Adjusted EBITDA | B17: 898 | C17: 486 | D17: 3093 | E17: 1219
A18: Revenue | B18: 1572 | C18: 747 | D18: 5131 | E18: 1915
A19: Net loss margin | B19: -29 | C19: -7 | D19: -23 | E19: -45
A20: Adjusted EBITDA margin | B20: 57 | C20: 65 | D20: 60 | E20: 64
A21: (1) Acquisition related costs include direct transaction costs, such as due diligence, advisory, and professional services fees, and certain compensation and integration related expenses. We exclude acquisition related costs, as we believe these transaction-specific expenses are inconsistent in amount and frequency, and do not correlate to the operation of our business.
A22: (2) Represents adjustments related to recording our derivative liabilities at fair value at the end of each reporting period for our 2021 Convertible Senior Secured Notes, warrant liabilities related to our 2022 Senior Secured Notes, and the fair value remeasurement of the option liability in connection with our Series B redeemable convertible preferred stock. Refer to Note 3. Investments and Fair Value Measurements to our consolidated financial statements included in our Annual Report on Form 10-K filed or to be filed with the SEC for the year ended December 31, 2025 for additional information.
A24: Reconciliation of Operating Income to Adjusted Operating Income (in millions, except percentages)
B25: Three Months Ended December 31, | D25: Twelve Months Ended December 31,
B26: 2025 | C26: 2024 | D26: 2025 | E26: 2024
A27: Operating income (loss) | B27: -89 | C27: 113 | D27: -46 | E27: 324
A28: Stock-based compensation | B28: 157 | C28: 8 | D28: 630 | E28: 32
A29: Acquisition related costs(1) | B29: 9 | C29: 0 | D29: 55 | E29: 0
A30: Amortization of acquired intangibles(2) | B30: 11 | C30: 0 | D30: 27 | E30: 0
A31: Adjusted operating income | B31: 88 | C31: 121 | D31: 666 | E31: 356
A32: Revenue | B32: 1572 | C32: 747 | D32: 5131 | E32: 1915
A33: Operating income margin | B33: -6 | C33: 15 | D33: -1 | E33: 17
A34: Adjusted operating income margin | B34: 6 | C34: 16 | D34: 13 | E34: 19
A35: (1) Acquisition related costs include direct transaction costs, such as due diligence, advisory, and professional services fees, and certain compensation and integration related expenses. We exclude acquisition related costs, as we believe these transaction-specific expenses are inconsistent in amount and frequency, and do not correlate to the operation of our business.
A36: (2) In the second quarter of 2025, we began including an adjustment for the amortization of acquired intangibles in our calculation of adjusted operating income (loss). Prior period non-GAAP calculations for acquired intangible amortization are not being adjusted as these amounts were insignificant.
A38: Reconciliation of Net Loss to Adjusted Net Loss (in millions, except percentages)
B39: Three Months Ended December 31, | D39: Twelve Months Ended December 31,
B40: 2025 | C40: 2024 | D40: 2025 | E40: 2024
A41: Net loss | B41: -452 | C41: -51 | D41: -1167 | E41: -863
A42: Stock-based compensation | B42: 157 | C42: 8 | D42: 630 | E42: 31
A43: Loss on extinguishment of debt(1) | B43: 4 | C43: 0 | D43: 29 | E43: 0
...

Sheet Subsequent
A1: Subsequent events known on the analysis date (2026-08-13)
A2: Word for word. Events AFTER 2026-08-13 are deliberately excluded (e.g., the September 2026 convertible notes).
A4: ¶ | B4: Document / section | C4: Text (verbatim)
A5: A. 10-Q Q2 2026, Note 16 - Subsequent Events
A6: https://www.sec.gov/Archives/edgar/data/1769628/000176962826000366/R22.htm
A7: 1 | B7: Note 16 | C7: In August 2026, one of the Company's indirect subsidiaries, CoreWeave Financing DDTL V-V, LLC entered into a delayed draw term loan facility agreement with various lenders and JPMorgan Chase Bank, N.A., as the administrative agent. The agreement provides a $2.6 billion delayed draw term loan facility (the “DDTL 5.5 Facility”) available in one or more draws through the commitment termination date in December 2026. Interest on outstanding borrowings on the DDTL 5.5 Facility accrues for SOFR loans at an interest rate per annum equal to the Term SOFR plus an applicable margin of 5.5% or for base rate loans at the applicable base rate plus 4.5% per annum, at the Company's election. The DDTL 5.5 Facility matures in September 2031. Subsequent to the closing, the Company has drawn $1.2 billion.
A8: 2 | B8: Note 16 | C8: In August 2026, the Company made a $1.2 billion draw down on the Revolving Credit Facility.
A10: B. 8-K filed 2026-08-10 (event date 2026-08-07), Items 1.01 and 2.03
A11: https://www.sec.gov/Archives/edgar/data/1769628/000176962826000357/crwv-20260807.htm
A12: 1 | B12: 8-K body | C12: Item 1.01 Entry into a Material Definitive Agreement.On August 7, 2026, CoreWeave Financing DDTL V-V, LLC (the “Borrower”), a Delaware limited liability company and an indirect subsidiary of CoreWeave, Inc., a Delaware corporation (the “Parent”), entered into a credit agreement (the “Credit Agreement”) with, inter alios, JPMorgan Chase Bank, N.A., as administrative agent, U.S. Bank Trust Company, National Association, as collateral agent, U.S. Bank National Association, as depositary bank, JPMorgan Chase Bank, N.A. and MUFG Bank, Ltd. as joint lead arrangers, joint bookrunners and syndication agents, and the lenders party thereto, providing for a $2.6 billion delayed draw term loan facility (the “DDTL 5.5 Facility”). The DDTL 5.5 Facility was entered into primarily to finance capital expenditures required to perform certain customer contracts, including the acquisition of GPU servers and related infrastructure.
A13: 2 | B13: 8-K body | C13: Availability and MaturityThe DDTL 5.5 Facility provides for delayed draw term loans available in one or more draws until the commitment termination date in December 2026. The maturity date of the DDTL 5.5 Facility is September 1, 2031.
A14: 3 | B14: 8-K body | C14: Interest Rate and FeesAmounts borrowed under the DDTL 5.5 Facility are subject to an interest rate per annum equal to (i) for SOFR loans, Term SOFR (subject to a 0.00% floor) plus an applicable margin of 5.50% per annum, and (ii) for base rate loans, the base rate (determined by reference to the highest of (A) the prime rate, (B) the federal funds effective rate plus 0.50% and (C) Term SOFR for a one-month tenor plus 1.00%) (subject to a 0.00% floor), plus an applicable margin of 4.50% per annum. The DDTL 5.5 Facility provides for payment of, among others, undrawn fees in an amount equal to 0.50% per annum on the average daily undrawn portion of the DDTL 5.5 Facility, which undrawn fees are payable monthly in arrears.
A15: 4 | B15: 8-K body | C15: Guarantees and SecurityAll obligations under the DDTL 5.5 Facility are unconditionally guaranteed by the Parent pursuant to a parent guarantee and pledge agreement, dated as of August 7, 2026, by and among the Parent, CW Financing DDTL V-V Holdco, LLC, a Delaware limited liability company, and U.S. Bank Trust Company, National Association (the “Parent Guarantee and Pledge Agreement”), and all obligations under the DDTL 5.5 Facility are also unconditionally guaranteed by the subsidiaries of the Borrower pursuant to a collateral agreement. All obligations under the DDTL 5.5 Facility are secured by substantially all assets of the Borrower and its subsidiaries and a pledge of 100% of the equity interests in the Borrower held by CW Financing DDTL V-V Holdco, LLC.
A16: 5 | B16: 8-K body | C16: CovenantsThe Borrower is required to comply with the following covenants, among others described in the Credit Agreement:
A17: 6 | B17: 8-K body | C17: Debt Service Coverage Ratio. Beginning the first full calendar month after the earlier to occur of (a) the date on which the commitments are reduced to zero and (b) December 31, 2026, the Borrower is required to maintain a debt service coverage ratio of at least 1.35x.
A18: 7 | B18: 8-K body | C18: Certain Other Covenants and Events of Default. The DDTL 5.5 Facility contains a number of other customary negative covenants, and the Credit Agreement contains customary events of default, including payment defaults, failure to perform or observe covenants, cross-defaults with certain other indebtedness, a change of control, and certain bankruptcy events. The Credit Agreement also contains events of default related to certain adverse events with respect to certain material contracts.
A19: 8 | B19: 8-K body | C19: The foregoing summary of the DDTL 5.5 Facility does not purport to be complete and is qualified in its entirety by reference to the complete terms of the Credit Agreement and the Parent Guarantee and Pledge Agreement, which are filed as Exhibits 10.1 and 10.2 hereto respectively, and incorporated by reference into this Item 1.01.
A20: 9 | B20: 8-K body | C20: Item 2.03 Creation of a Direct Financial Obligation or an Obligation under an Off-Balance Sheet Arrangement of a Registrant.The information described above under Item 1.01 is incorporated into this Item 2.03 by reference.
A22: C. Same 8-K, Exhibit 99.1 press release (closing 'About CoreWeave' boilerplate omitted)
A23: https://www.sec.gov/Archives/edgar/data/1769628/000176962826000357/ex991pr.htm
A24: 1 | B24: Ex.99.1 | C24: COREWEAVE CLOSES $2.6 BILLION LOAN FACILITY, EXPANDING FINANCING FLEXIBILITY FOR AI INFRASTRUCTURE
A25: 2 | B25: Ex.99.1 | C25: ●Facility is backed by a diverse group of leading AI, financial services, and technology customers
A26: 3 | B26: Ex.99.1 | C26: ●Facility’s approximate five-year maturity extends beyond the average three-year length of underlying customer contracts, reflecting lender confidence in long-term GPU demand
A27: 4 | B27: Ex.99.1 | C27: ●Innovative structure allows CoreWeave to efficiently finance shorter-dated contracts, unlocking a broader base of enterprise customers and higher-margin deals
A28: 5 | B28: Ex.99.1 | C28: LIVINGSTON, N.J. — AUGUST 10, 2026 — CoreWeave, Inc. (Nasdaq: CRWV), The Essential Cloud for AI™, today announced it has closed its $2.6 billion delayed draw term loan facility (“DDTL 5.5 Facility”), supporting the continued expansion of its AI cloud platform and committed customer deployments.
A29: 6 | B29: Ex.99.1 | C29: The DDTL 5.5 Facility extends CoreWeave’s HPC infrastructure-backed financing platform by broadening the scope of customer contracts eligible for publicly syndicated infrastructure financing. Unlike prior delayed draw term loan facilities backed by customer contracts extending through the maturity of the debt, the DDTL 5.5 Facility carries an approximate five-year maturity while its underlying customer contracts average approximately three years in length. By financing these shorter-date commitments, lenders are signalling confidence in the long-term value of NVIDIA GPUs running on CoreWeave’s cloud platform and a willingness to underwrite renewal risk. These shorter duration customer contracts also often command higher prices, which CoreWeave expects to allow it to capture higher margins while expanding market reach.
A30: 7 | B30: Ex.99.1 | C30: “This transaction demonstrates the continued evolution and growing flexibility of AI infrastructure financing and represents a major unlock for CoreWeave,” said Brannin McBee, co-founder and chief development officer at CoreWeave. “Lenders are now comfortable financing shorter-dated contracts, which allows us to target a wider variety of customers, including global enterprises that typically favor shorter-term agreements.”
A31: 8 | B31: Ex.99.1 | C31: The facility received ratings of Ba2 from Moody’s and BB+ from Fitch, reflecting the strength of the collateral and structural protections supporting the transaction.
A32: 9 | B32: Ex.99.1 | C32: Proceeds from the DDTL 5.5 Facility will support the purchase and deployment of HPC-backed infrastructure dedicated to customer contracts. The facility includes the option for CoreWeave to either renew existing contracts or re-lease capacity to other customers at the end of the initial underlying contracts, subject to the criteria described in the credit agreement for the DDTL 5.5 Facility.
A33: 10 | B33: Ex.99.1 | C33: The transaction was meaningfully oversubscribed, attracting exceptional investor demand, and priced at SOFR + 5.50%. The DDTL 5.5 Facility was issued through CoreWeave Financing DDTL V-V, LLC.
A34: 11 | B34: Ex.99.1 | C34: JPMorgan and Mitsubishi UFJ Financial Group served as joint lead arrangers and bookrunners for the transaction.
A35: 12 | B35: Ex.99.1 | C35: The DDTL 5.5 Facility builds on CoreWeave’s continued capital markets momentum and follows the company’s previously announced $3.1 billion DDTL 5.0 facility completed earlier this year. With the closing of this transaction, CoreWeave has secured more than $30 billion of debt and equity capital year-to-date, representing a significant step in CoreWeave's evolution as it continues to scale its global footprint and service offerings for a larger and more diverse set of customers.
A37: D. Same 8-K, Exhibit 10.2 Parent Guarantee and Pledge Agreement - Section 2.1(a)-(b) only (the full agreement is ~98,000 characters)
A38: https://www.sec.gov/Archives/edgar/data/1769628/000176962826000357/ex102parentguarantee.htm
A39: 1 | B39: Ex.10.2 s.2.1 | C39: Section 2.1Guarantee.(a)Subject to the provisions of Section 2.1(b), the Guarantor hereby unconditionally and irrevocably guarantees, as a primary obligor and not merely a surety, the prompt and complete payment and performance when due (whether at the stated maturity, by acceleration, demand or otherwise) of the Guaranteed Obligations and whether at stated maturity, by acceleration, demand or otherwise, and whether such Guaranteed Obligations are now existing or hereafter incurred (including any extensions, modifications, substitutions, amendments and renewals of any or all of such Guaranteed Obligations). Guarantor further agrees that the Guaranteed Obligations may be extended, increased, renewed, amended or modified, in whole or in part, without notice to, or further assent from Guarantor, and that Guarantor will remain bound upon its guarantee hereunder notwithstanding any such extension, increase, renewal, amendment or modification of any Guaranteed Obligations. Guarantor waives, to the fullest extent permitted under applicable Law, presentment to, demand of payment from, and protest to, the Borrower or any other Person of any of the Guaranteed Obligations, and also waives, to the fullest extent permitted under applicable Law, notice of acceptance of its guarantee and notice of protest for nonpayment.
A40: 2 | B40: Ex.10.2 s.2.1 | C40: (b)Anything herein or in the Credit Agreement to the contrary notwithstanding, as of any date of determination the maximum liability of the Guarantor hereunder shall in no event exceed the amount that is the lesser of (i) the outstanding Guaranteed Obligations as of such date of determination and (ii) the maximum liability which can be guaranteed by the Guarantor under the Bankruptcy Code or any applicable federal and state requirements of Law relating to fraudulent conveyances, fraudulent transfers or the insolvency of debtors.

Sheet Guidance
A1: Company guidance and capex definition - Q2 2026 earnings materials (2026-08-11)
A2: Word for word from the company's IR website (investors.coreweave.com > Financials > Quarterly Results). Guidance is forward-looking and not in the 10-Q. Anything published after 2026-08-13 (e.g., Q3'26 results) is excluded.
A4: A. Q3 and FY 2026 Outlook Presentation, slide 3 'Guidance'
A5: https://s205.q4cdn.com/133937190/files/doc_financials/2026/q2/CoreWeave-Q2-26-Earnings-Outlook-Presentation.pdf
A6: Q3'26 Guidance | D6: FY'26 Guidance
A7: Revenue | B7: $3.45 – 3.60 billion | D7: Revenue | E7: $12.4 – 13.2 billion
A8: Adjusted Operating Income | B8: $200 – 260 million | D8: Adjusted Operating Income | E8: $960 – 1,150 million
A9: Interest Expense | B9: $860 – 940 million | D9: Capital Expenditures | E9: $35 – 39 billion
A10: Capital Expenditures | B10: $11.5 – 13.5 billion | D10: Exiting 2026 ARR 1 | E10: $18.5 – 19.5 billion
A11: Note: 1. Annualized run-rate revenue (ARR) is calculated by taking revenue from the last month of the quarter multiplied by 12
A13: B. Q2'26 Earnings Presentation - slide 16 'Capital Expenditures Calculation' (in millions)
A14: https://s205.q4cdn.com/133937190/files/doc_financials/2026/q2/CoreWeave-Q2-26-Earnings-Presentation.pdf
B15: Three Months Ended June 30, | D15: Six Months Ended June 30,
B16: 2025 | C16: 2026 | D16: 2025 | E16: 2026
A17: Increase in total gross property and equipment | B17: 2975 | C17: 11689 | D17: 5705 | E17: 18681
A18: Less: Change in construction in progress | B18: 37 | C18: 2337 | D18: 910 | E18: 2542
A19: Capital expenditures 1 | B19: 2938 | C19: 9352 | D19: 4795 | E19: 16139
A20: Check: increase - change in CIP - capex (should be 0) | B20: =B17-B18-B19 | C20: =C17-C18-C19 | D20: =D17-D18-D19 | E20: =E17-E18-E19
A21: Note: 1. Capital expenditures are additions to property and equipment including assets acquired under finance leases, less changes in construction in progress
A23: Slide 14 'Capital Expenditures' chart (Note: $ in billions)
B24: Q2'25 | C24: Q3'25 | D24: Q4'25 | E24: Q1'26 | F24: Q2'26
A25: Capital Expenditures 1 | B25: 2.9 | C25: 1.9 | D25: 8.2 | E25: 6.8 | F25: 9.4
A26: Slide title: 'Capital Expenditures: $9.4 billion as we continued to execute on schedule'
A27: Note: 1. Capital expenditures are additions to property and equipment including assets acquired under finance leases, less changes in construction in progress
A28: Slide 8 'Q2'26 Highlights', note 3 (worded slightly differently): 3. Capital expenditures are additions to property and equipment plus assets acquired under finance leases, less changes to construction in progress
A30: C. Q2 2026 earnings call, 2026-08-11 - key points (paraphrased; the transcript is FactSet copyright, see link)
A31: https://s205.q4cdn.com/133937190/files/doc_financials/2026/q2/CRWV-US-CORRECTED-TRANSCRIPT-CoreWeave-Q2-2026-Earnings-Call-11August2026.pdf
A32: ¶ | B32: Speaker | C32: Key points (paraphrased, figures as stated on the call)
A33: 1 | B33: Nitin Agrawal, CFO (prepared remarks) | C33: Q2 capex was $9.4bn, slightly above the high end of guidance; construction in progress rose to $11.9bn from $9.6bn, capacity expected to be deployed early in Q3.
A34: 2 | B34: Nitin Agrawal, CFO (prepared remarks) | C34: At June 30 the company had more than $6.9bn of cash, cash equivalents, restricted cash and marketable securities; it raised about $18bn across debt, convertibles and equity in Q2.
A35: 3 | B35: Nitin Agrawal, CFO (prepared remarks) | C35: Year-end active power now expected above 1.85 GW (previously above 1.7 GW); Q3 revenue guided to $3.45-3.6bn and Q3 adjusted operating income to $200-260m.
A36: 4 | B36: Nitin Agrawal, CFO (prepared remarks) | C36: Q3 interest expense guided to $860-940m, reflecting a larger debt balance; Q3 capex guided to $11.5-13.5bn.
A37: 5 | B37: Nitin Agrawal, CFO (prepared remarks) | C37: FY26 guidance raised: revenue $12.4-13.2bn, adjusted operating income $0.96-1.15bn, capex $35-39bn, exiting-2026 ARR $18.5-19.5bn.
A38: 6 | B38: Irvin Liu, Evercore ISI (Q&A question) | C38: Analyst question referenced a target of more than 3 GW of active power by end-2027 and 8 GW by 2030.
A39: 7 | B39: Nitin Agrawal, CFO (Q&A answer) | C39: CFO: 4.2 GW contracted today plus ~1.5 GW of powered land/options; on track for more than 8 GW of active power by end-2030.
A40: Paraphrased from the corrected transcript linked above; see the original for exact wording.

Sheet Cross_Checks
A1: Cross-document checks (ours) - the same number should match across filings
A2: Green = link to another tab. Difference column should be 0; where it is not, the Comment explains why.
A4: Check | B4: Value A | C4: Value B | D4: Difference | E4: Comment
A5: Total assets Dec-25: 10-Q comparative vs 10-K | B5: ='10Q_BS'!C20 | C5: ='10K_BS'!C21 | D5: =B5-C5
A6: Debt, current Dec-25: 10-Q (recourse + non-recourse) vs 10-K (one line) | B6: ='10Q_BS'!C24+'10Q_BS'!C25 | C6: ='10K_BS'!C25 | D6: =B6-C6 | E6: 10-K showed one 'Debt' line; the 10-Q re-presents Dec-25 split into recourse / non-recourse
A7: Debt, non-current Dec-25: 10-Q split vs 10-K | B7: ='10Q_BS'!C31+'10Q_BS'!C32 | C7: ='10K_BS'!C31 | D7: =B7-C7
A8: Other non-current liabilities Dec-25: 10-Q vs 10-K (other + derivative/warrant) | B8: ='10Q_BS'!C37 | C8: ='10K_BS'!C37+'10K_BS'!C32 | D8: =B8-C8 | E8: 10-Q folds the 10-K's 'Derivative and warrant liabilities' line into 'Other'
A9: Total equity Dec-25: 10-Q vs 10-K | B9: ='10Q_BS'!C46 | C9: ='10K_BS'!C45 | D9: =B9-C9
A10: Cash end of 6M26 (CF, thousands /1000) vs BS cash + restricted | B10: ='10Q_CF'!B47/1000 | C10: ='10Q_BS'!B8+'10Q_BS'!B9+'10Q_BS'!B14 | D10: =B10-C10 | E10: R page CF is in thousands
A11: Net loss 6M26: 10-Q CF (/1000) vs 10-Q IS | B11: ='10Q_CF'!B9/1000 | C11: ='10Q_IS'!D22 | D11: =B11-C11
A12: Net loss Q2-26: press release vs 10-Q IS | B12: ='PR_Q2-26'!B9 | C12: ='10Q_IS'!B22 | D12: =B12-C12
A13: Operating income 6M26: press release vs 10-Q IS | B13: ='PR_Q2-26'!D27 | C13: ='10Q_IS'!D16 | D13: =B13-C13
A14: Interest expense 6M26: press release (add-back) vs 10-Q IS | B14: ='PR_Q2-26'!D11 | C14: =-'10Q_IS'!D18 | D14: =B14-C14 | E14: Sign flips: IS shows expense as negative; reconciliation adds it back
A15: D&A 6M26: press release vs 10-Q CF (/1000) | B15: ='PR_Q2-26'!D10 | C15: ='10Q_CF'!B11/1000 | D15: =B15-C15
A16: Net loss FY25: Q4 release vs 10-K IS | B16: ='PR_Q4-25'!D9 | C16: ='10K_IS'!C22 | D16: =B16-C16
A17: Other income FY24: Q4 release EBITDA table vs 10-K IS | B17: =-'PR_Q4-25'!E15 | C17: ='10K_IS'!D19 | D17: =B17-C17 | E17: Release subtracts 48; IS shows 49 - a 1mm inconsistency in the company's own tables
